#VRML_SIM R2023b utf8

EXTERNPROTO "https://raw.githubusercontent.com/cyberbotics/webots/R2023b/projects/objects/backgrounds/protos/TexturedBackground.proto"
EXTERNPROTO "https://raw.githubusercontent.com/cyberbotics/webots/R2023b/projects/objects/backgrounds/protos/TexturedBackgroundLight.proto"
EXTERNPROTO "https://raw.githubusercontent.com/cyberbotics/webots/R2023b/projects/objects/floors/protos/RectangleArena.proto"
EXTERNPROTO "https://raw.githubusercontent.com/cyberbotics/webots/R2023b/projects/objects/apartment_structure/protos/Wall.proto"

WorldInfo {
}
Viewpoint {
  orientation 0.42268031672732015 -0.4260722607435551 -0.7998773521460452 4.666125967743058
  position 0.9019912902341588 -2.3489390049252803 1.6288041591951044
}
TexturedBackground {
}
TexturedBackgroundLight {
}
RectangleArena {
  translation -0.08 0 0
  floorSize 5.5 5
  floorTileSize 1 1
}
Robot {
  translation 1.0702104588773267 -0.7406423683055146 0.039720979298946156
  rotation -2.754033810786626e-08 -1.6418791519320055e-08 0.9999999999999996 1.065270355682181
  children [
    DEF BODY Shape {
      appearance PBRAppearance {
        baseColor 0.917647 0.145098 0.145098
        roughness 1
        metalness 0
      }
      geometry Box {
        size 0.2 0.1 0.05
      }
    }
    DEF WHEEL1 HingeJoint {
      jointParameters HingeJointParameters {
        position 16007.777633956342
        axis 0 1 0
        anchor 0.05 0.06 0
      }
      device [
        RotationalMotor {
          name "wheel1"
        }
      ]
      endPoint Solid {
        translation 0.05 0.06 0
        rotation 0.49756136125863015 -0.6133636474159755 0.6133659004305912 2.2182059923103976
        children [
          DEF WHEEL Shape {
            appearance PBRAppearance {
              baseColor 0.305882 0.898039 0.25098
              roughness 1
              metalness 0
            }
            geometry Cylinder {
              height 0.02
              radius 0.04
              subdivision 24
            }
          }
        ]
        boundingObject USE WHEEL
        physics Physics {
        }
        linearVelocity 0.03874121692940518 0.06999302767080674 -2.4870019379968036e-09
        angularVelocity -1.749839752242936 0.9685353160902663 1.786268602168764e-08
      }
    }
    DEF WHEEL2 HingeJoint {
      jointParameters HingeJointParameters {
        position 17247.910204019
        axis 0 1 0
        anchor 0.05 -0.06 0
      }
      device [
        RotationalMotor {
          name "wheel2"
        }
      ]
      endPoint Solid {
        translation 0.05 -0.06 0
        rotation -0.9247086504015621 -0.26917780329551727 0.2691787920426151 4.6341885688456586
        children [
          USE WHEEL
        ]
        name "solid(1)"
        boundingObject USE WHEEL
        physics Physics {
        }
        linearVelocity 0.038741148981006765 0.06999316094775263 2.3643490065394e-09
        angularVelocity -1.7498397557538554 0.9685353235303827 -1.688904042843715e-08
      }
    }
    DEF WHEEL3 HingeJoint {
      jointParameters HingeJointParameters {
        position 16007.887456753146
        axis 0 1 0
        anchor -0.05 0.06 0
      }
      device [
        RotationalMotor {
          name "wheel3"
        }
      ]
      endPoint Solid {
        translation -0.05 0.06 0
        rotation 0.5396843391959214 -0.5952890939183616 0.5952912805413143 2.151818051946596
        children [
          USE WHEEL
        ]
        name "solid(2)"
        boundingObject USE WHEEL
        physics Physics {
        }
        linearVelocity 0.03874167870618817 0.06999403421052008 -2.36849680306673e-09
        angularVelocity -1.7498398284630914 0.9685353602247292 1.3929880157696128e-08
      }
    }
    DEF WHEEL4 HingeJoint {
      jointParameters HingeJointParameters {
        position 17247.91248648873
        axis 0 1 0
        anchor -0.05 -0.06 0
      }
      device [
        RotationalMotor {
          name "wheel4"
        }
      ]
      endPoint Solid {
        translation -0.05 -0.06 0
        rotation -0.9241379035599764 -0.2701560651079301 0.27015705744838847 4.633573062010453
        children [
          USE WHEEL
        ]
        name "solid(3)"
        boundingObject USE WHEEL
        physics Physics {
        }
        linearVelocity 0.03874161004490671 0.06999414385216202 2.482856615224807e-09
        angularVelocity -1.7498398305901022 0.9685353667030601 -2.035612487050184e-08
      }
    }
    DEF DS_RIGHT DistanceSensor {
      translation 0.1 -0.03 0
      rotation 0 0 1 -0.3
      children [
        Shape {
          appearance PBRAppearance {
            baseColor 0.184314 0.596078 0.847059
            roughness 1
            metalness 0
          }
          geometry Box {
            size 0.01 0.01 0.01
          }
        }
      ]
      name "ds_right"
    }
    DEF DS_LEFT DistanceSensor {
      translation 0.1 0.03 0
      rotation 0 0 1 0.3
      children [
        Shape {
          appearance PBRAppearance {
            baseColor 0.184314 0.596078 0.847059
            roughness 1
            metalness 0
          }
          geometry Box {
            size 0.01 0.01 0.01
          }
        }
      ]
      name "ds_left"
    }
    DEF DS_LEFT DistanceSensor {
      translation 0.095382 -0.00205471 0.03
      rotation 0 0 -1 -0.038205307179586256
      children [
        Shape {
          appearance PBRAppearance {
            baseColor 0.184314 0.596078 0.847059
            roughness 1
            metalness 0
          }
          geometry Box {
            size 0.01 0.01 0.01
          }
        }
      ]
      name "ds_left(1)"
    }
    Lidar {
      translation 0.095382 -0.00205471 0.03
      fieldOfView 3.14
      numberOfLayers 1
    }
  ]
  boundingObject USE BODY
  physics Physics {
    density -1
    mass 1
  }
  controller "test"
  linearVelocity 0.03874141366582969 0.06999359167116774 -2.0728713353027694e-12
  angularVelocity -2.1027083180770645e-08 -3.549302820940066e-08 6.247638141215213e-08
}
Wall {
  translation 2.2 -0.35 0
  name "wall(2)"
  size 0.1 4.3 0.3
}
Wall {
  translation 1.5 0.55 0
  name "wall(3)"
  size 0.1 3.8 0.3
}
Wall {
  translation -0.1 -1.3 0
  rotation 0 0 1 1.5707996938995747
  name "wall(4)"
  size 0.1 3.2 0.3
}
Wall {
  translation -1.7 0.2 0
  rotation 0 0 1 3.141592653589793
  name "wall(5)"
  size 0.1 3 0.3
}
Wall {
  translation -0.9 1 0
  rotation 0 0 1 3.141592653589793
  name "wall(6)"
  size 0.1 3.2 0.3
}
Wall {
  translation 0 1 0
  rotation 0 0 1 3.141592653589793
  name "wall(1)"
  size 0.1 3.2 0.3
}
Wall {
  translation -0.5 -0.5 0
  rotation 0 0 1 -1.5707996938995747
  name "wall(7)"
  size 0.1 0.8 0.3
}
